Workbook
Name Data: 'DEP ALIM MODIF'!$A$1:$AQ$347

Sheet Depenses restau 2025
A1: Numéro | B1: N° bordereau | C1: N° mandat/titre | D1: Libellé | E1: Saisie le | F1: Montant HT | G1: Montant TVA | H1: Montant TTC | I1: Tiers (Code) | J1: Tiers (Nom) | K1: Engagement | L1: Marché | M1: Lot | N1: Contrat | O1: Gestionnaire | P1: Fonction | Q1: Nature | R1: Opération | S1: Service | T1: Antenne | U1: Code subvention | V1: Libellé subvention | W1: Millésime | X1: Réf. dossier | Y1: Enveloppe
A2: 401932 | B2: 19 | C2: 135 | D2: FAC. 9100490723 DU 16/01/2025 RS24011001R - RATT RESTAURATION TOUS SITES NOVEMBRE ET DECEM | E2: 45698 | F2: 546.45 | G2: 30.06 | H2: 576.51 | I2: 8930 | J2: SCOLAREST COMPASS GROUP FRANCE | K2: RS24011001R | L2: 23003PA | M2: 001 | P2: 281 | Q2: 6042 | S2: 2-RE
A3: 401933 | B3: 19 | C3: 136 | D3: FAC. 9100490713 DU 16/01/2025 RS24011001R - RATT RESTAURATION TOUS SITES NOVEMBRE ET DECEM | E3: 45698 | F3: 440.06 | G3: 24.2 | H3: 464.26 | I3: 8930 | J3: SCOLAREST COMPASS GROUP FRANCE | K3: RS24011001R | L3: 23003PA | M3: 001 | P3: 281 | Q3: 6042 | S3: 2-RE
A4: 401935 | B4: 19 | C4: 137 | D4: RATTACHE FAC. 9100488685 DU 07/01/2025 RS24011001R - RATT RESTAURATION TOUS SITES NOVEMBRE ET DECEM | E4: 45698 | F4: 19508.61 | G4: 1072.97 | H4: 20581.58 | I4: 8930 | J4: SCOLAREST COMPASS GROUP FRANCE | K4: RS24011001R | L4: 23003PA | M4: 001 | P4: 281 | Q4: 6042 | S4: 2-RE
A5: 401936 | B5: 19 | C5: 137 | D5: RATTACHE FAC. 9100488685 DU 07/01/2025 RS25002801 - RESTAURATION SCOLAIRE 1ER TRIMESTREREPAS POUR L | E5: 45698 | F5: 30293.52 | G5: 1666.14 | H5: 31959.66 | I5: 8930 | J5: SCOLAREST COMPASS GROUP FRANCE | K5: RS25002801 | L5: 23003PA | M5: 001 | P5: 281 | Q5: 6042 | S5: 2-RE
A6: 403041 | B6: 25 | C6: 174 | D6: FAC. 9100503210 DU 31/01/2025 Restauration scolaire Période 01.01.2025 au 31.01.2025 | E6: 45706 | F6: 62325.38 | G6: 3427.9 | H6: 65753.28 | I6: 8930 | J6: SCOLAREST COMPASS GROUP FRANCE | K6: RS25002801 | L6: 23003PA | M6: 001 | P6: 281 | Q6: 6042 | S6: 2-RE
A7: 403097 | B7: 31 | C7: 232 | D7: FAC. 9100503291 DU 31/01/2025 REPAS LM JANVIER | E7: 45709 | F7: 4422.03 | G7: 243.21 | H7: 4665.24 | I7: 8930 | J7: SCOLAREST COMPASS GROUP FRANCE | K7: RS25003001 | L7: 23003PA | M7: 001 | P7: 331 | Q7: 6042 | S7: 2-RE | T7: RESTMICH
A8: 403098 | B8: 31 | C8: 233 | D8: FAC. 9100503218 DU 31/01/2025 REPAS RC JANVIER | E8: 45709 | F8: 382.23 | G8: 21.02 | H8: 403.25 | I8: 8930 | J8: SCOLAREST COMPASS GROUP FRANCE | K8: RS25003201 | L8: 23003PA | M8: 001 | P8: 020 | Q8: 6042 | S8: 2-RE | T8: RESTCOMM
A9: 403099 | B9: 31 | C9: 234 | D9: FAC. 9100504971 DU 31/01/2025 REPAS PP JANVIER | E9: 45709 | F9: 4147.84 | G9: 228.13 | H9: 4375.97 | I9: 8930 | J9: SCOLAREST COMPASS GROUP FRANCE | K9: RS25002901 | L9: 23003PA | M9: 001 | P9: 331 | Q9: 6042 | S9: 2-RE | T9: RESTGAV
A10: 403106 | B10: 31 | C10: 241 | D10: FAC. 9100509029 DU 17/02/2025 REPAS CA JANVIER | E10: 45709 | F10: 199.37 | G10: 10.97 | H10: 210.34 | I10: 8930 | J10: SCOLAREST COMPASS GROUP FRANCE | K10: RS25003101 | L10: 23003PA | M10: 001 | P10: 338 | Q10: 6042 | S10: 2-RE | T10: RESTCA
A11: 403203 | B11: 42 | C11: 285 | D11: FAC. 9100503227 DU 31/01/2025 RESTAURATION CRECHE JANVIER | E11: 45715 | F11: 3569.64 | G11: 196.33 | H11: 3765.97 | I11: 8930 | J11: SCOLAREST COMPASS GROUP FRANCE | K11: ME25000101 | L11: 23003PA | M11: 001 | P11: 4221 | Q11: 6042 | S11: 6-MP | T11: CRCOLL
A12: 406094 | B12: 69 | C12: 533 | D12: FAC. 9100507827 DU 12/02/2025 RS25004701 - CARTON DE 250 SACS POUR LE RESTAURANT COMMUNAL | E12: 45736 | F12: 167.49 | G12: 33.5 | H12: 200.99 | I12: 8930 | J12: SCOLAREST COMPASS GROUP FRANCE | K12: RS25004701 | L12: 23003PA | M12: 001 | P12: 020 | Q12: 6042 | S12: 2-RE | T12: RESTCOMM
A13: 406095 | B13: 69 | C13: 534 | D13: FAC. 9100516880 DU 28/02/2025 RESTAURATION DES ENFANTS DE LA CRECHE FEVRIER | E13: 45736 | F13: 2809.38 | G13: 154.52 | H13: 2963.9 | I13: 8930 | J13: SCOLAREST COMPASS GROUP FRANCE | K13: ME25000101 | L13: 23003PA | M13: 001 | P13: 4221 | Q13: 6042 | S13: 6-MP | T13: CRCOLL
A14: 406096 | B14: 69 | C14: 535 | D14: FAC. 9100520585 DU 28/02/2025 RESTAURATION SCOLAIRE 1ER TRIMESTRE ECOLE FEVRIER | E14: 45736 | F14: 31011.98 | G14: 1705.66 | H14: 32717.64 | I14: 8930 | J14: SCOLAREST COMPASS GROUP FRANCE | K14: RS25002801 | L14: 23003PA | M14: 001 | P14: 281 | Q14: 6042 | S14: 2-RE
A15: 406097 | B15: 69 | C15: 536 | D15: FAC. 9100521148 DU 28/02/2025 RESTAURATION CENTRE DE LOISIRS LOUISE MICHEL FEVRIER | E15: 45736 | F15: 9713.07 | G15: 534.22 | H15: 10247.29 | I15: 8930 | J15: SCOLAREST COMPASS GROUP FRANCE | K15: RS25003001 | L15: 23003PA | M15: 001 | P15: 331 | Q15: 6042 | S15: 2-RE | T15: RESTMICH
A16: 406098 | B16: 69 | C16: 537 | D16: FAC. 9100522762 DU 07/03/2025 REPAS RESTAURANT COMMUNAL 1ER TRIMESTRE FEVRIER | E16: 45736 | F16: 382.23 | G16: 21.02 | H16: 403.25 | I16: 8930 | J16: SCOLAREST COMPASS GROUP FRANCE | K16: RS25003201 | L16: 23003PA | M16: 001 | P16: 020 | Q16: 6042 | S16: 2-RE | T16: RESTCOMM
A17: 406099 | B17: 69 | C17: 538 | D17: FAC. 9100522867 DU 10/03/2025 RESTAURATION CENTRE DE LOISIRS LE PETIT PRINCE FEVRIER | E17: 45736 | F17: 7898.46 | G17: 434.42 | H17: 8332.88 | I17: 8930 | J17: SCOLAREST COMPASS GROUP FRANCE | K17: RS25002901 | L17: 23003PA | M17: 001 | P17: 331 | Q17: 6042 | S17: 2-RE | T17: RESTGAV
A18: 406100 | B18: 69 | C18: 539 | D18: FAC. 9100523011 DU 10/03/2025 RESTAURATION ESPACE ADOS 1ER TRIMESTRE FEVRIER | E18: 45736 | F18: 487.35 | G18: 26.8 | H18: 514.15 | I18: 8930 | J18: SCOLAREST COMPASS GROUP FRANCE | K18: RS25003101 | L18: 23003PA | M18: 001 | P18: 338 | Q18: 6042 | S18: 2-RE | T18: RESTCA
A19: 407926 | B19: 93 | C19: 708 | D19: FAC. 9100533274 DU 31/03/2025 RS25002801 - RESTAURATION SCOLAIRE 1ER TRIMESTREREPAS POUR L | E19: 45758 | F19: 37506.56 | G19: 2062.86 | H19: 39569.42 | I19: 8930 | J19: SCOLAREST COMPASS GROUP FRANCE | K19: RS25002801 | L19: 23003PA | M19: 001 | P19: 281 | Q19: 6042 | S19: 2-RE
A20: 407927 | B20: 93 | C20: 708 | D20: FAC. 9100533274 DU 31/03/2025 RS25004801 - COMPLEMENT POUR LA RESTAURATION SCOLAIRE DE MAR | E20: 45758 | F20: 28436.02 | G20: 1563.98 | H20: 30000 | I20: 8930 | J20: SCOLAREST COMPASS GROUP FRANCE | K20: RS25004801 | L20: 23003PA | M20: 001 | P20: 281 | Q20: 6042 | S20: 2-RE
A21: 407928 | B21: 93 | C21: 708 | D21: FAC. 9100533274 DU 31/03/2025 RS25004901 - RESTAURATION SCOLAIRE AVRIL 2025REPAS POUR LES | E21: 45758 | F21: 725.07 | G21: 39.88 | H21: 764.95 | I21: 8930 | J21: SCOLAREST COMPASS GROUP FRANCE | K21: RS25004901 | L21: 23003PA | M21: 001 | P21: 281 | Q21: 6042 | S21: 2-RE
A22: 407929 | B22: 93 | C22: 709 | D22: FAC. 9100533155 DU 31/03/2025 RS25003001 - RESTAURATION CENTRE DE LOISIRS LOUISE MICHEL 1E | E22: 45758 | F22: 3331.51 | G22: 183.23 | H22: 3514.74 | I22: 8930 | J22: SCOLAREST COMPASS GROUP FRANCE | K22: RS25003001 | L22: 23003PA | M22: 001 | P22: 331 | Q22: 6042 | S22: 2-RE | T22: RESTMICH
A23: 407944 | B23: 96 | C23: 722 | D23: FAC. 9100533335 DU 31/03/2025 RS25002901 - RESTAURATION CENTRE DE LOISIRS LE PETIT PRINCE | E23: 45761 | F23: 3092.16 | G23: 170.07 | H23: 3262.23 | I23: 8930 | J23: SCOLAREST COMPASS GROUP FRANCE | K23: RS25002901 | L23: 23003PA | M23: 001 | P23: 331 | Q23: 6042 | S23: 2-RE | T23: RESTGAV
A24: 407952 | B24: 96 | C24: 729 | D24: FAC. 9100540729 DU 07/04/2025 RS25003201 - REPAS RESTAURANT COMMUNAL 1ER TRIMESTRE | E24: 45761 | F24: 372.99 | G24: 20.51 | H24: 393.5 | I24: 8930 | J24: SCOLAREST COMPASS GROUP FRANCE | K24: RS25003201 | L24: 23003PA | M24: 001 | P24: 020 | Q24: 6042 | S24: 2-RE | T24: RESTCOMM
A25: 407953 | B25: 96 | C25: 730 | D25: FAC. 9100540729 DU 07/04/2025 RS25005201 - REPAS RESTAURANT COMMUNAL AVRIL 2025 | E25: 45761 | F25: 161.01 | G25: 8.86 | H25: 169.87 | I25: 8930 | J25: SCOLAREST COMPASS GROUP FRANCE | K25: RS25005201 | L25: 23003PA | M25: 001 | P25: 020 | Q25: 6042 | S25: 2-RE | T25: RESTCOMM
A26: 407925 | B26: 97 | C26: 733 | D26: FAC. 9100533352 DU 31/03/2025 ME25000101 - RESTAURATION DES ENFANTS DE LA CRECHE Repas et | E26: 45758 | F26: 3471.97 | G26: 190.96 | H26: 3662.93 | I26: 8930 | J26: SCOLAREST COMPASS GROUP FRANCE | K26: ME25000101 | L26: 23003PA | M26: 001 | P26: 4221 | Q26: 6042 | S26: 6-MP | T26: CRCOLL
A27: 409339 | B27: 137 | C27: 938 | D27: FAC. 9100551618 DU 30/04/2025 RS25005201 - REPAS RESTAURANT COMMUNAL AVRIL 2025 | E27: 45790 | F27: 312.92 | G27: 17.21 | H27: 330.13 | I27: 8930 | J27: SCOLAREST COMPASS GROUP FRANCE | K27: RS25005201 | L27: 23003PA | M27: 001 | P27: 020 | Q27: 6042 | S27: 2-RE | T27: RESTCOMM
A28: 409340 | B28: 137 | C28: 939 | D28: FAC. 9100551618 DU 30/04/2025 RS25006001 - REPAS RESTAURANT COMMUNAL AVRIL 2025 - COMPLEME | E28: 45790 | F28: 80.55 | G28: 4.43 | H28: 84.98 | I28: 8930 | J28: SCOLAREST COMPASS GROUP FRANCE | K28: RS25006001 | L28: 23003PA | M28: 001 | P28: 020 | Q28: 6042 | S28: 2-RE | T28: RESTCOMM
A29: 409341 | B29: 137 | C29: 940 | D29: FAC. 9100551632 DU 30/04/2025 RS25005001 - RESTAURATION ACCUEIL DE LOISIRS PETIT PRINCE AV | E29: 45790 | F29: 7228.61 | G29: 397.57 | H29: 7626.18 | I29: 8930 | J29: SCOLAREST COMPASS GROUP FRANCE | K29: RS25005001 | L29: 23003PA | M29: 001 | P29: 331 | Q29: 6042 | S29: 2-RE | T29: RESTGAV
A30: 409358 | B30: 142 | C30: 970 | D30: FAC. 9100554578 DU 30/04/2025 RS25005101 - RESTAURATION ACCUEIL DE LOUISE MICHEL AVRIL 202 | E30: 45791 | F30: 8442.05 | G30: 464.31 | H30: 8906.36 | I30: 8930 | J30: SCOLAREST COMPASS GROUP FRANCE | K30: RS25005101 | L30: 23003PA | M30: 001 | P30: 331 | Q30: 6042 | S30: 2-RE | T30: RESTMICH
A31: 409359 | B31: 142 | C31: 971 | D31: FAC. 9100554523 DU 30/04/2025 RS25004901 - RESTAURATION SCOLAIRE AVRIL 2025REPAS POUR LES | E31: 45791 | F31: 30554.55 | G31: 1680.5 | H31: 32235.05 | I31: 8930 | J31: SCOLAREST COMPASS GROUP FRANCE | K31: RS25004901 | L31: 23003PA | M31: 001 | P31: 281 | Q31: 6042 | S31: 2-RE
A32: 409360 | B32: 142 | C32: 972 | D32: FAC. 9100554523 DU 30/04/2025 RS25006101 - RESTAURATION SCOLAIRE AVRIL 2025 COMPLEMENTREPA | E32: 45791 | F32: 1292.49 | G32: 71.09 | H32: 1363.58 | I32: 8930 | J32: SCOLAREST COMPASS GROUP FRANCE | K32: RS25006101 | L32: 23003PA | M32: 001 | P32: 281 | Q32: 6042 | S32: 2-RE
A33: 409361 | B33: 142 | C33: 973 | D33: FAC. 9100554533 DU 30/04/2025 ME25000101 - RESTAURATION DES ENFANTS DE LA CRECHE Repas et | E33: 45791 | F33: 3023.92 | G33: 166.32 | H33: 3190.24 | I33: 8930 | J33: SCOLAREST COMPASS GROUP FRANCE | K33: ME25000101 | L33: 23003PA | M33: 001 | P33: 4221 | Q33: 6042 | S33: 6-MP | T33: CRCOLL
A34: 409972 | B34: 166 | C34: 1115 | D34: FACTURE N°9100479000 DU 23/12/2024 | E34: 45814 | F34: 3488.17 | G34: 697.63 | H34: 4185.8 | I34: 8930 | J34: SCOLAREST COMPASS GROUP FRANCE | P34: 331 | Q34: 6042 | S34: 2-RE | T34: RESTMICH
A35: 409973 | B35: 166 | C35: 1116 | D35: FACTURE N°9100478999 DU 23/12/2024 | E35: 45814 | F35: 3430.04 | G35: 686.01 | H35: 4116.05 | I35: 8930 | J35: SCOLAREST COMPASS GROUP FRANCE | P35: 331 | Q35: 6042 | S35: 2-RE | T35: RESTGAV
A36: 409988 | B36: 172 | C36: 1146 | D36: FAC. 9100564477 DU 29/05/2025 ME25000101 - RESTAURATION DES ENFANTS DE LA CRECHE Repas et | E36: 45814 | F36: 2961.54 | G36: 162.88 | H36: 3124.42 | I36: 8930 | J36: SCOLAREST COMPASS GROUP FRANCE | K36: ME25000101 | L36: 23003PA | M36: 001 | P36: 4221 | Q36: 6042 | S36: 6-MP | T36: CRCOLL
A37: 411303 | B37: 198 | C37: 1322 | D37: FAC. 9100571391 DU 31/05/2025 RS25006301 - REPAS RESTAURANT COMMUNAL MAI 2025 | E37: 45840 | F37: 398.1 | G37: 21.9 | H37: 420 | I37: 8930 | J37: SCOLAREST COMPASS GROUP FRANCE | K37: RS25006301 | L37: 23003PA | M37: 001 | P37: 020 | Q37: 6042 | S37: 2-RE | T37: RESTCOMM
A38: 411309 | B38: 201 | C38: 1332 | D38: FAC. 9100571388 DU 31/05/2025 RS25006201 - RESTAURATION SCOLAIRE MAI 2025REPAS POUR LES EC | E38: 45841 | F38: 50363.11 | G38: 2769.97 | H38: 53133.08 | I38: 8930 | J38: SCOLAREST COMPASS GROUP FRANCE | K38: RS25006201 | L38: 23003PA | M38: 001 | P38: 281 | Q38: 6042 | S38: 2-RE
A39: 412277 | B39: 227 | C39: 1531 | D39: FAC. 9100578104 DU 25/06/2025 RS25003101 - RESTAURATION ESPACE ADOS 1ER TRIMESTREUNIQUEMEN | E39: 45853 | F39: 819.62 | G39: 45.08 | H39: 864.7 | I39: 8930 | J39: SCOLAREST COMPASS GROUP FRANCE | K39: RS25003101 | L39: 23003PA | M39: 001 | P39: 338 | Q39: 6042 | S39: 2-RE | T39: RESTCA
A40: 412733 | B40: 243 | C40: 1584 | D40: FAC. 9100571404 DU 31/05/2025 RS25002901 - RESTAURATION CENTRE DE LOISIRS LE PETIT PRINCE | E40: 45863 | F40: 2992.21 | G40: 164.57 | H40: 3156.78 | I40: 8930 | J40: SCOLAREST COMPASS GROUP FRANCE | K40: RS25002901 | L40: 23003PA | M40: 001 | P40: 331 | Q40: 6042 | S40: 2-RE | T40: RESTGAV
...

Sheet Depenses,service,RE
B3: Antenne
A4: Service | B4: CRCOLL | C4: RESTCA | D4: Total général
A5: 2-RE | C5: 9511.68 | D5: 9511.68
A6: SCOLAREST COMPASS GROUP FRANCE | C6: 9511.68 | D6: 9511.68
A7: RS25003101 | C7: 1840.1 | D7: 1840.1
A8: RS25008301 | C8: 5000 | D8: 5000
A9: RS25008901 | C9: 1000 | D9: 1000
A10: RS25010101 | C10: 1671.58 | D10: 1671.58
A11: 6-MP | B11: 33523.42 | D11: 33523.42
A12: SCOLAREST COMPASS GROUP FRANCE | B12: 33523.42 | D12: 33523.42
A13: ME25000101 | B13: 33523.42 | D13: 33523.42
A14: Total général | B14: 33523.42 | C14: 9511.68 | D14: 43035.1

Sheet DEP ALIM
A1: Type écriture | B1: Nb. ann/rej | C1: Exercice | D1: Budget | E1: N° écriture | F1: N° pièce | G1: N° bordereau | H1: N° ordre | I1: Date pièce | J1: Lot | K1: Libellé | L1: Montant HT | M1: Montant TVA | N1: Montant TTC | O1: Réf. dossier | P1: Date règlement | Q1: Montant pour le C.A. | R1: Engagement | S1: Solde eng. | T1: Marché | U1: Reconduction | V1: Lot | W1: Tranche | X1: Ligne | Y1: Avenant | Z1: Mt révision HT | AA1: Mt révision TVA | AB1: Mt révision TTC | AC1: Code contrat | AD1: Code tiers | AE1: Libellé tiers | AF1: Gestionnaire | AG1: Fonction | AH1: Nature | AI1: Opération | AJ1: Pgm (opé) | AK1: Service | AL1: Antenne | AM1: Chapitre | AN1: Libellé chapitre | AO1: Cha. voté | AP1: Libellé chapitre voté | AQ1: Nomenclature | AR1: Libellé nomenclature | AS1: Type dep. | AT1: Objectif | AU1: Code famille Nomemclature | AV1: Libellé famille Nomenclature | AW1: Ligne AGEC | AX1: Montant réemploi ou réutilisation | AY1: Taux minimum | AZ1: Montant matières recyclées | BA1: Taux minimum | BB1: Inscription | BC1: Immobilisation | BD1: N° inventaire | BE1: Programme | BF1: Année d’AP | BG1: Engagement AP | BH1: N° facture | BI1: Nombre PJ | BJ1: Nombre CA | BK1: Début Prestation | BL1: Fin Prestation | BM1: Objet Prestation | BN1: Prise en charge | BO1: Acquittement du flux | BP1: Montant payé/encaissé | BQ1: Génération du flux
A2: Ann. rattachement | C2: 2025 | D2: CR | E2: 401475 | F2: 3 | G2: 1 | H2: 0 | I2: 45698 | J2: FIN | K2: RATT VIENNOISERIES LEGISLATIVES 30 JUIN | L2: -92.56 | M2: -5.09 | N2: -97.65 | Q2: -97.65 | S2: 0 | Z2: 0 | AA2: 0 | AB2: 0 | AD2: 163 | AE2: CENTRE DES FINANCES PUBLIQUES YE | AG2: 026 | AH2: 60623 | AK2: 0-AG | AL2: ETATCIV | AM2: 011 | AN2: CHARGES A CARACTERE GENERAL | AO2: 011 | AP2: CHARGES A CARACTERE GENERAL | BB2: CPRAT - RATT VIENNOISERIES LEGISLATIVES 30 JUIN | BI2: 0 | BJ2: 0 | BO2: 45818 | BP2: 0 | BQ2: 45698
A3: Ann. rattachement | C3: 2025 | D3: CR | E3: 401499 | F3: 11 | G3: 1 | H3: 0 | I3: 45698 | J3: FIN | K3: RATT PATISSERIE, VEILLEE, CHOCOLAT DE NOËL, GOUTER DE F IN D 'ANNEE | L3: -850.98 | M3: -170.2 | N3: -1021.18 | Q3: -1021.18 | S3: 0 | Z3: 0 | AA3: 0 | AB3: 0 | AD3: 163 | AE3: CENTRE DES FINANCES PUBLIQUES YE | AG3: 331 | AH3: 60623 | AK3: 4-CT | AL3: CLGAV | AM3: 011 | AN3: CHARGES A CARACTERE GENERAL | AO3: 011 | AP3: CHARGES A CARACTERE GENERAL | BB3: CPRAT - RATT PATISSERIE, VEILLEE, CHOCOLAT DE NOËL, GOUTER DE F IN D | BI3: 0 | BJ3: 0 | BO3: 45818 | BP3: 0 | BQ3: 45698
A4: Ann. rattachement | C4: 2025 | D4: CR | E4: 401538 | F4: 23 | G4: 1 | H4: 0 | I4: 45698 | J4: FIN | K4: RATT GOUTERS VACANCES NOEL 2024 | L4: -166.12 | M4: -33.22 | N4: -199.34 | Q4: -199.34 | S4: 0 | Z4: 0 | AA4: 0 | AB4: 0 | AD4: 163 | AE4: CENTRE DES FINANCES PUBLIQUES YE | AG4: 338 | AH4: 60623 | AK4: 4-JE | AL4: CA | AM4: 011 | AN4: CHARGES A CARACTERE GENERAL | AO4: 011 | AP4: CHARGES A CARACTERE GENERAL | BB4: CPRAT - RATT GOUTERS VACANCES NOEL 2024 | BI4: 0 | BJ4: 0 | BO4: 45818 | BP4: 0 | BQ4: 45698
A5: Ann. rattachement | C5: 2025 | D5: CR | E5: 401547 | F5: 26 | G5: 1 | H5: 0 | I5: 45698 | J5: FIN | K5: RATT GOUTER MDJ | L5: -165.89 | M5: -33.18 | N5: -199.07 | Q5: -199.07 | S5: 0 | Z5: 0 | AA5: 0 | AB5: 0 | AD5: 163 | AE5: CENTRE DES FINANCES PUBLIQUES YE | AG5: 338 | AH5: 60623 | AK5: 4-JE | AL5: MDJ | AM5: 011 | AN5: CHARGES A CARACTERE GENERAL | AO5: 011 | AP5: CHARGES A CARACTERE GENERAL | BB5: CPRAT - RATT GOUTER MDJ | BI5: 0 | BJ5: 0 | BO5: 45818 | BP5: 0 | BQ5: 45698
A6: Ann. rattachement | C6: 2025 | D6: CR | E6: 401574 | F6: 34 | G6: 1 | H6: 0 | I6: 45698 | J6: FIN | K6: RATT RESTAURANT COMMUNAL | L6: -21.8 | M6: -1.2 | N6: -23 | Q6: -23 | S6: 0 | Z6: 0 | AA6: 0 | AB6: 0 | AD6: 163 | AE6: CENTRE DES FINANCES PUBLIQUES YE | AG6: 020 | AH6: 60623 | AK6: 2-RE | AL6: RESTCOMM | AM6: 011 | AN6: CHARGES A CARACTERE GENERAL | AO6: 011 | AP6: CHARGES A CARACTERE GENERAL | BB6: CPRAT - RATT RESTAURANT COMMUNAL | BI6: 0 | BJ6: 0 | BO6: 45818 | BP6: 0 | BQ6: 45698
A7: Ann. rattachement | C7: 2025 | D7: CR | E7: 401577 | F7: 35 | G7: 1 | H7: 0 | I7: 45698 | J7: FIN | K7: RATT RESTAURATION SCOLAIRE | L7: -864.45 | M7: -47.55 | N7: -912 | Q7: -912 | S7: 0 | Z7: 0 | AA7: 0 | AB7: 0 | AD7: 163 | AE7: CENTRE DES FINANCES PUBLIQUES YE | AG7: 281 | AH7: 60623 | AK7: 2-RE | AM7: 011 | AN7: CHARGES A CARACTERE GENERAL | AO7: 011 | AP7: CHARGES A CARACTERE GENERAL | BB7: CPRAT - RATT RESTAURATION SCOLAIRE | BI7: 0 | BJ7: 0 | BO7: 45818 | BP7: 0 | BQ7: 45698
A8: Ann. rattachement | C8: 2025 | D8: CR | E8: 401580 | F8: 36 | G8: 1 | H8: 0 | I8: 45698 | J8: FIN | K8: RATT ACCUEIL JP1 | L8: -34.12 | M8: -1.88 | N8: -36 | Q8: -36 | S8: 0 | Z8: 0 | AA8: 0 | AB8: 0 | AD8: 163 | AE8: CENTRE DES FINANCES PUBLIQUES YE | AG8: 331 | AH8: 60623 | AK8: 2-RE | AL8: CLJP1 | AM8: 011 | AN8: CHARGES A CARACTERE GENERAL | AO8: 011 | AP8: CHARGES A CARACTERE GENERAL | BB8: CPRAT - RATT ACCUEIL JP1 | BI8: 0 | BJ8: 0 | BO8: 45818 | BP8: 0 | BQ8: 45698
A9: Ann. rattachement | C9: 2025 | D9: CR | E9: 401583 | F9: 37 | G9: 1 | H9: 0 | I9: 45698 | J9: FIN | K9: RATT ACCUEIL LE PETIT PRINCE | L9: -99.53 | M9: -5.47 | N9: -105 | Q9: -105 | S9: 0 | Z9: 0 | AA9: 0 | AB9: 0 | AD9: 163 | AE9: CENTRE DES FINANCES PUBLIQUES YE | AG9: 331 | AH9: 60623 | AK9: 2-RE | AL9: RESTGAV | AM9: 011 | AN9: CHARGES A CARACTERE GENERAL | AO9: 011 | AP9: CHARGES A CARACTERE GENERAL | BB9: CPRAT - RATT ACCUEIL LE PETIT PRINCE | BI9: 0 | BJ9: 0 | BO9: 45818 | BP9: 0 | BQ9: 45698
A10: Ann. rattachement | C10: 2025 | D10: CR | E10: 401586 | F10: 38 | G10: 1 | H10: 0 | I10: 45698 | J10: FIN | K10: RATT ACCUEIL LOUISE MICHEL | L10: -142.18 | M10: -7.82 | N10: -150 | Q10: -150 | S10: 0 | Z10: 0 | AA10: 0 | AB10: 0 | AD10: 163 | AE10: CENTRE DES FINANCES PUBLIQUES YE | AG10: 331 | AH10: 60623 | AK10: 2-RE | AL10: RESTMICH | AM10: 011 | AN10: CHARGES A CARACTERE GENERAL | AO10: 011 | AP10: CHARGES A CARACTERE GENERAL | BB10: CPRAT - RATT ACCUEIL LOUISE MICHEL | BI10: 0 | BJ10: 0 | BO10: 45818 | BP10: 0 | BQ10: 45698
A11: Ann. rattachement | C11: 2025 | D11: CR | E11: 401589 | F11: 39 | G11: 1 | H11: 0 | I11: 45698 | J11: FIN | K11: RATT ESPACE ADOS | L11: -18.96 | M11: -1.04 | N11: -20 | Q11: -20 | S11: 0 | Z11: 0 | AA11: 0 | AB11: 0 | AD11: 163 | AE11: CENTRE DES FINANCES PUBLIQUES YE | AG11: 338 | AH11: 60623 | AK11: 2-RE | AL11: RESTCA | AM11: 011 | AN11: CHARGES A CARACTERE GENERAL | AO11: 011 | AP11: CHARGES A CARACTERE GENERAL | BB11: CPRAT - RATT ESPACE ADOS | BI11: 0 | BJ11: 0 | BO11: 45818 | BP11: 0 | BQ11: 45698
A12: Ann. rattachement | C12: 2025 | D12: CR | E12: 401637 | F12: 55 | G12: 1 | H12: 0 | I12: 45698 | J12: FIN | K12: RATT MINI VIENNOISERIES JP1 | L12: -389.43 | M12: -21.42 | N12: -410.85 | Q12: -410.85 | S12: 0 | Z12: 0 | AA12: 0 | AB12: 0 | AD12: 163 | AE12: CENTRE DES FINANCES PUBLIQUES YE | AG12: 201 | AH12: 60623 | AK12: 2-SC | AM12: 011 | AN12: CHARGES A CARACTERE GENERAL | AO12: 011 | AP12: CHARGES A CARACTERE GENERAL | BB12: CPRAT - RATT MINI VIENNOISERIES JP1 | BI12: 0 | BJ12: 0 | BO12: 45818 | BP12: 0 | BQ12: 45698
A13: Mandat ordinaire | C13: 2025 | D13: CR | E13: 401938 | F13: 65 | G13: 11 | H13: 0 | I13: 45698 | J13: ARFF | K13: FAC. 14D DU 31/12/2024 RS24009004R - RATT ACCUEIL LE PETIT PRINCE | L13: 28.16 | M13: 1.55 | N13: 29.71 | P13: 45701 | Q13: 29.71 | R13: RS24009004R | S13: 0 | Z13: 0 | AA13: 0 | AB13: 0 | AD13: 5384 | AE13: SAS VERMAR L ORGE ET LE BLE | AG13: 331 | AH13: 60623 | AK13: 2-RE | AL13: RESTGAV | AM13: 011 | AN13: CHARGES A CARACTERE GENERAL | AO13: 011 | AP13: CHARGES A CARACTERE GENERAL | BB13: CPRAT - RATT ACCUEIL LE PETIT PRINCE | BH13: 20250140 | BI13: 1 | BJ13: 0 | BN13: 45701 | BO13: 45701 | BP13: 29.71 | BQ13: 45700
A14: Mandat ordinaire | C14: 2025 | D14: CR | E14: 401939 | F14: 64 | G14: 11 | H14: 0 | I14: 45698 | J14: ARFF | K14: FAC. 16D DU 31/12/2024 RS24009001R - RATT RESTAURANT COMMUNAL | L14: 19.36 | M14: 1.06 | N14: 20.42 | P14: 45701 | Q14: 20.42 | R14: RS24009001R | S14: 0 | Z14: 0 | AA14: 0 | AB14: 0 | AD14: 5384 | AE14: SAS VERMAR L ORGE ET LE BLE | AG14: 020 | AH14: 60623 | AK14: 2-RE | AL14: RESTCOMM | AM14: 011 | AN14: CHARGES A CARACTERE GENERAL | AO14: 011 | AP14: CHARGES A CARACTERE GENERAL | BB14: CPRAT - RATT RESTAURANT COMMUNAL | BH14: 20250139 | BI14: 1 | BJ14: 0 | BN14: 45701 | BO14: 45701 | BP14: 20.42 | BQ14: 45700
A15: Mandat ordinaire | C15: 2025 | D15: CR | E15: 401940 | F15: 63 | G15: 11 | H15: 0 | I15: 45698 | J15: ARFF | K15: FAC. 12DEC DU 31/12/2024 RS24009002R - RATT RESTAURATION SCOLAIRE | L15: 696.96 | M15: 38.33 | N15: 735.29 | P15: 45701 | Q15: 735.29 | R15: RS24009002R | S15: 0 | Z15: 0 | AA15: 0 | AB15: 0 | AD15: 5384 | AE15: SAS VERMAR L ORGE ET LE BLE | AG15: 281 | AH15: 60623 | AK15: 2-RE | AM15: 011 | AN15: CHARGES A CARACTERE GENERAL | AO15: 011 | AP15: CHARGES A CARACTERE GENERAL | BB15: CPRAT - RATT RESTAURATION SCOLAIRE | BH15: 20250138 | BI15: 1 | BJ15: 0 | BN15: 45701 | BO15: 45701 | BP15: 735.29 | BQ15: 45700
A16: Mandat ordinaire | C16: 2025 | D16: CR | E16: 401942 | F16: 62 | G16: 11 | H16: 0 | I16: 45698 | J16: ARFF | K16: FAC. 13D DU 31/12/2024 RS24009003R - RATT ACCUEIL JP1 | L16: 28.16 | M16: 1.55 | N16: 29.71 | P16: 45701 | Q16: 29.71 | R16: RS24009003R | S16: 0 | Z16: 0 | AA16: 0 | AB16: 0 | AD16: 5384 | AE16: SAS VERMAR L ORGE ET LE BLE | AG16: 331 | AH16: 60623 | AK16: 2-RE | AL16: CLJP1 | AM16: 011 | AN16: CHARGES A CARACTERE GENERAL | AO16: 011 | AP16: CHARGES A CARACTERE GENERAL | BB16: CPRAT - RATT ACCUEIL JP1 | BH16: 20250137 | BI16: 1 | BJ16: 0 | BN16: 45701 | BO16: 45701 | BP16: 29.71 | BQ16: 45700
A17: Mandat ordinaire | C17: 2025 | D17: CR | E17: 401943 | F17: 61 | G17: 11 | H17: 0 | I17: 45698 | J17: ARFF | K17: FAC. 15D DU 31/12/2024 RS24009005R - RATT ACCUEIL LOUISE MICHEL | L17: 41.36 | M17: 2.27 | N17: 43.63 | P17: 45701 | Q17: 43.63 | R17: RS24009005R | S17: 0 | Z17: 0 | AA17: 0 | AB17: 0 | AD17: 5384 | AE17: SAS VERMAR L ORGE ET LE BLE | AG17: 331 | AH17: 60623 | AK17: 2-RE | AL17: RESTMICH | AM17: 011 | AN17: CHARGES A CARACTERE GENERAL | AO17: 011 | AP17: CHARGES A CARACTERE GENERAL | BB17: CPRAT - RATT ACCUEIL LOUISE MICHEL | BH17: 20250136 | BI17: 1 | BJ17: 0 | BN17: 45701 | BO17: 45701 | BP17: 43.63 | BQ17: 45700
A18: Mandat ordinaire | C18: 2025 | D18: CR | E18: 402989 | F18: 148 | G18: 22 | H18: 5 | I18: 45705 | J18: RADE | K18: REGULARISATION RA 20052 ETATS 7.8 | L18: 115.88 | M18: 23.18 | N18: 139.06 | P18: 45720 | Q18: 139.06 | S18: 0 | Z18: 0 | AA18: 0 | AB18: 0 | AD18: 1462 | AE18: RA 20052 AFFAIRES GENERALES | AG18: 020 | AH18: 60623 | AK18: 0-CA | AL18: CAB | AM18: 011 | AN18: CHARGES A CARACTERE GENERAL | AO18: 011 | AP18: CHARGES A CARACTERE GENERAL | BI18: 1 | BJ18: 0 | BN18: 45720 | BO18: 45714 | BP18: 139.06 | BQ18: 45713
A19: Mandat ordinaire | C19: 2025 | D19: CR | E19: 402990 | F19: 148 | G19: 22 | H19: 6 | I19: 45705 | J19: RADE | K19: REGULARISATION RA 20052 ETATS 6.10.11.12 | L19: 338.21 | M19: 67.64 | N19: 405.85 | P19: 45720 | Q19: 405.85 | S19: 0 | Z19: 0 | AA19: 0 | AB19: 0 | AD19: 1462 | AE19: RA 20052 AFFAIRES GENERALES | AG19: 311 | AH19: 60623 | AK19: 3-CU | AM19: 011 | AN19: CHARGES A CARACTERE GENERAL | AO19: 011 | AP19: CHARGES A CARACTERE GENERAL | BI19: 1 | BJ19: 0 | BN19: 45720 | BO19: 45714 | BP19: 405.85 | BQ19: 45713
A20: Mandat ordinaire | C20: 2025 | D20: CR | E20: 403011 | F20: 182 | G20: 28 | H20: 0 | I20: 45706 | J20: CSFF | K20: RATT FAC. 2412HY1319371 DU 23/12/2024 JS24011601R - RATT GOUTERS VACANCES NOEL 2024 | L20: 185.57 | M20: 13.77 | N20: 199.34 | P20: 45715 | Q20: 199.34 | R20: JS24011601R | S20: 0 | Z20: 0 | AA20: 0 | AB20: 0 | AD20: 1507 | AE20: AUCHAN HYPERMARCHE | AG20: 338 | AH20: 60623 | AK20: 4-JE | AL20: CA | AM20: 011 | AN20: CHARGES A CARACTERE GENERAL | AO20: 011 | AP20: CHARGES A CARACTERE GENERAL | BB20: CPRAT - RATT GOUTERS VACANCES NOEL 2024 | BH20: 20234517 | BI20: 1 | BJ20: 0 | BN20: 45715 | BO20: 45714 | BP20: 199.34 | BQ20: 45713
A21: Mandat ordinaire | C21: 2025 | D21: CR | E21: 403075 | F21: 203 | G21: 28 | H21: 0 | I21: 45706 | J21: CSFF | K21: FAC. 2502HY0226458 DU 17/02/2025 PATISSERIE 01 VACANCES HIVERS 2025 | L21: 46.23 | M21: 2.54 | N21: 48.77 | P21: 45715 | Q21: 48.77 | R21: JS25000601 | S21: 0 | Z21: 0 | AA21: 0 | AB21: 0 | AD21: 1507 | AE21: AUCHAN HYPERMARCHE | AG21: 338 | AH21: 60623 | AK21: 4-JE | AL21: CA | AM21: 011 | AN21: CHARGES A CARACTERE GENERAL | AO21: 011 | AP21: CHARGES A CARACTERE GENERAL | BH21: 20250313 | BI21: 1 | BJ21: 0 | BN21: 45715 | BO21: 45714 | BP21: 48.77 | BQ21: 45713
A22: Mandat ordinaire | C22: 2025 | D22: CR | E22: 403082 | F22: 246 | G22: 34 | H22: 0 | I22: 45712 | J22: MMFF | K22: Goûter vacances scolaires d'hiver 2025 FAC. 2502HY0232115 DU 18/02/2025 | L22: 181.58 | M22: 11.46 | N22: 193.04 | P22: 45714 | Q22: 193.04 | R22: JS25000501 | S22: 0 | Z22: 0 | AA22: 0 | AB22: 0 | AD22: 1507 | AE22: AUCHAN HYPERMARCHE | AG22: 338 | AH22: 60623 | AK22: 4-JE | AL22: CA | AM22: 011 | AN22: CHARGES A CARACTERE GENERAL | AO22: 011 | AP22: CHARGES A CARACTERE GENERAL | BH22: 20250338 | BI22: 1 | BJ22: 0 | BN22: 45714 | BO22: 45713 | BP22: 193.04 | BQ22: 45712
A23: Mandat ordinaire | C23: 2025 | D23: CR | E23: 403084 | F23: 245 | G23: 34 | H23: 0 | I23: 45712 | J23: MMFF | K23: Repas au club 01 vacances hiver 2025 FAC. 2502HY0232145 DU 18/02/2025 | L23: 127.93 | M23: 7.04 | N23: 134.97 | P23: 45714 | Q23: 134.97 | R23: JS25000801 | S23: 0 | Z23: 0 | AA23: 0 | AB23: 0 | AD23: 1507 | AE23: AUCHAN HYPERMARCHE | AG23: 338 | AH23: 60623 | AK23: 4-JE | AL23: CA | AM23: 011 | AN23: CHARGES A CARACTERE GENERAL | AO23: 011 | AP23: CHARGES A CARACTERE GENERAL | BH23: 20250334 | BI23: 1 | BJ23: 0 | BN23: 45714 | BO23: 45713 | BP23: 134.97 | BQ23: 45712
A24: Mandat ordinaire | C24: 2025 | D24: CR | E24: 403107 | F24: 219 | G24: 30 | H24: 0 | I24: 45709 | J24: CSFF | K24: FAC. 487 DU 31/01/2025 PAIN RESTAURANT COMMUNAL JANVIER | L24: 28.83 | M24: 1.59 | N24: 30.42 | P24: 45714 | Q24: 30.42 | R24: RS25001001 | S24: 0 | Z24: 0 | AA24: 0 | AB24: 0 | AD24: 7485 | AE24: SAS PATAUX LA CERISE SUR LE GATE | AG24: 020 | AH24: 60623 | AK24: 2-RE | AL24: RESTCOMM | AM24: 011 | AN24: CHARGES A CARACTERE GENERAL | AO24: 011 | AP24: CHARGES A CARACTERE GENERAL | BH24: 20250324 | BI24: 1 | BJ24: 0 | BN24: 45714 | BO24: 45713 | BP24: 30.42 | BQ24: 45712
A25: Mandat ordinaire | C25: 2025 | D25: CR | E25: 403108 | F25: 220 | G25: 30 | H25: 0 | I25: 45709 | J25: CSFF | K25: FAC. 486 DU 31/01/2025 PAIN ACCUEIL LM JANVIER | L25: 66.54 | M25: 3.66 | N25: 70.2 | P25: 45714 | Q25: 70.2 | R25: RS25000801 | S25: 0 | Z25: 0 | AA25: 0 | AB25: 0 | AD25: 7485 | AE25: SAS PATAUX LA CERISE SUR LE GATE | AG25: 331 | AH25: 60623 | AK25: 2-RE | AL25: RESTMICH | AM25: 011 | AN25: CHARGES A CARACTERE GENERAL | AO25: 011 | AP25: CHARGES A CARACTERE GENERAL | BH25: 20250325 | BI25: 1 | BJ25: 0 | BN25: 45714 | BO25: 45713 | BP25: 70.2 | BQ25: 45712
A26: Mandat ordinaire | C26: 2025 | D26: CR | E26: 403109 | F26: 221 | G26: 30 | H26: 0 | I26: 45709 | J26: CSFF | K26: FAC. 485 DU 31/01/2025 PAIN ACCUEIL PP JANVIER | L26: 53.23 | M26: 2.93 | N26: 56.16 | P26: 45714 | Q26: 56.16 | R26: RS25000701 | S26: 0 | Z26: 0 | AA26: 0 | AB26: 0 | AD26: 7485 | AE26: SAS PATAUX LA CERISE SUR LE GATE | AG26: 331 | AH26: 60623 | AK26: 2-RE | AL26: RESTGAV | AM26: 011 | AN26: CHARGES A CARACTERE GENERAL | AO26: 011 | AP26: CHARGES A CARACTERE GENERAL | BH26: 20250326 | BI26: 1 | BJ26: 0 | BN26: 45714 | BO26: 45713 | BP26: 56.16 | BQ26: 45712
A27: Mandat ordinaire | C27: 2025 | D27: CR | E27: 403110 | F27: 222 | G27: 30 | H27: 0 | I27: 45709 | J27: CSFF | K27: FAC. 484 DU 31/01/2025 PAIN ACCUEIL JP1 JANVIER | L27: 53.23 | M27: 2.93 | N27: 56.16 | P27: 45714 | Q27: 56.16 | R27: RS25000901 | S27: 0 | Z27: 0 | AA27: 0 | AB27: 0 | AD27: 7485 | AE27: SAS PATAUX LA CERISE SUR LE GATE | AG27: 331 | AH27: 60623 | AK27: 2-RE | AL27: CLJP1 | AM27: 011 | AN27: CHARGES A CARACTERE GENERAL | AO27: 011 | AP27: CHARGES A CARACTERE GENERAL | BH27: 20250327 | BI27: 1 | BJ27: 0 | BN27: 45714 | BO27: 45713 | BP27: 56.16 | BQ27: 45712
A28: Mandat ordinaire | C28: 2025 | D28: CR | E28: 403111 | F28: 223 | G28: 30 | H28: 0 | I28: 45709 | J28: CSFF | K28: FAC. 483 DU 31/01/2025 PAIN POUR LA RESTAURATION SCOLAIRE JANVIER | L28: 1255.39 | M28: 69.05 | N28: 1324.44 | P28: 45714 | Q28: 1324.44 | R28: RS25000601 | S28: 0 | Z28: 0 | AA28: 0 | AB28: 0 | AD28: 7485 | AE28: SAS PATAUX LA CERISE SUR LE GATE | AG28: 281 | AH28: 60623 | AK28: 2-RE | AM28: 011 | AN28: CHARGES A CARACTERE GENERAL | AO28: 011 | AP28: CHARGES A CARACTERE GENERAL | BH28: 20250328 | BI28: 1 | BJ28: 0 | BN28: 45714 | BO28: 45713 | BP28: 1324.44 | BQ28: 45712
A29: Mandat ordinaire | C29: 2025 | D29: CR | E29: 403112 | F29: 224 | G29: 30 | H29: 0 | I29: 45709 | J29: CSFF | K29: FAC. 455 DU 19/12/2024 RATT MINI VIENNOISERIES JP1 | L29: 389.43 | M29: 21.42 | N29: 410.85 | P29: 45714 | Q29: 410.85 | R29: SC24020701R | S29: 0 | Z29: 0 | AA29: 0 | AB29: 0 | AD29: 7485 | AE29: SAS PATAUX LA CERISE SUR LE GATE | AG29: 201 | AH29: 60623 | AK29: 2-SC | AM29: 011 | AN29: CHARGES A CARACTERE GENERAL | AO29: 011 | AP29: CHARGES A CARACTERE GENERAL | BB29: CPRAT - RATT MINI VIENNOISERIES JP1 | BH29: 20250329 | BI29: 1 | BJ29: 0 | BN29: 45714 | BO29: 45713 | BP29: 410.85 | BQ29: 45712
A30: Mandat ordinaire | C30: 2025 | D30: CR | E30: 403165 | F30: 271 | G30: 39 | H30: 0 | I30: 45714 | J30: MMFF | K30: VIENNOISERIES - LEGISLATIVES JUIN 2024 RATT FAC. 394 DU 28/06/2024 | L30: 92.56 | M30: 5.09 | N30: 97.65 | P30: 45726 | Q30: 97.65 | R30: AG24002701R | S30: 0 | Z30: 0 | AA30: 0 | AB30: 0 | AD30: 7485 | AE30: SAS PATAUX LA CERISE SUR LE GATE | AG30: 026 | AH30: 60623 | AK30: 0-AG | AL30: ETATCIV | AM30: 011 | AN30: CHARGES A CARACTERE GENERAL | AO30: 011 | AP30: CHARGES A CARACTERE GENERAL | BB30: CPRAT - RATT VIENNOISERIES LEGISLATIVES 30 JUIN | BH30: 20233053 | BI30: 1 | BJ30: 0 | BN30: 45726 | BO30: 45726 | BP30: 97.65 | BQ30: 45725
A31: Mandat ordinaire | C31: 2025 | D31: CR | E31: 403191 | F31: 267 | G31: 39 | H31: 0 | I31: 45714 | J31: MMFF | K31: HA goûter et petit-déjeuner - FA. 2501HY0123697 du 28.01.25 FAC. 2501HY0123697 DU 28/01/2025 | L31: 141.16 | M31: 8.52 | N31: 149.68 | P31: 45726 | Q31: 149.68 | R31: CL25000101 | S31: 0 | Z31: 0 | AA31: 0 | AB31: 0 | AD31: 1507 | AE31: AUCHAN HYPERMARCHE | AG31: 331 | AH31: 60623 | AK31: 4-CT | AL31: CLMICH | AM31: 011 | AN31: CHARGES A CARACTERE GENERAL | AO31: 011 | AP31: CHARGES A CARACTERE GENERAL | BH31: 20250168 | BI31: 1 | BJ31: 0 | BN31: 45726 | BO31: 45726 | BP31: 149.68 | BQ31: 45725
A32: Mandat ordinaire | C32: 2025 | D32: CR | E32: 403192 | F32: 268 | G32: 39 | H32: 0 | I32: 45714 | J32: MMFF | K32: HA repas CM2 du 29/01 - FAC. 2502HY0165620 DU 05/02/2025 CL25001001 - REPAS DES CHAMPIONS 29/01 REPAS DES CM2 SUR LA | L32: 119.61 | M32: 7.73 | N32: 127.34 | P32: 45726 | Q32: 127.34 | R32: CL25001001 | S32: 0 | Z32: 0 | AA32: 0 | AB32: 0 | AD32: 1507 | AE32: AUCHAN HYPERMARCHE | AG32: 331 | AH32: 60623 | AK32: 4-CT | AL32: CLMICH | AM32: 011 | AN32: CHARGES A CARACTERE GENERAL | AO32: 011 | AP32: CHARGES A CARACTERE GENERAL | BH32: 20250276 | BI32: 1 | BJ32: 0 | BN32: 45726 | BO32: 45726 | BP32: 127.34 | BQ32: 45725
A33: Mandat ordinaire | C33: 2025 | D33: CR | E33: 403193 | F33: 269 | G33: 39 | H33: 0 | I33: 45714 | J33: MMFF | K33: HA repas créole gp CP - FAC. 2502HY0232136 DU 18/02/2025 CL25002201 - REPAS CREOLE GROUPE DES CP 27/02 | L33: 93.69 | M33: 6.3 | N33: 99.99 | P33: 45726 | Q33: 99.99 | R33: CL25002201 | S33: 0 | Z33: 0 | AA33: 0 | AB33: 0 | AD33: 1507 | AE33: AUCHAN HYPERMARCHE | AG33: 331 | AH33: 60623 | AK33: 4-CT | AL33: CLMICH | AM33: 011 | AN33: CHARGES A CARACTERE GENERAL | AO33: 011 | AP33: CHARGES A CARACTERE GENERAL | BH33: 20250335 | BI33: 1 | BJ33: 0 | BN33: 45726 | BO33: 45726 | BP33: 99.99 | BQ33: 45725
A34: Mandat ordinaire | C34: 2025 | D34: CR | E34: 403194 | F34: 270 | G34: 39 | H34: 0 | I34: 45714 | J34: MMFF | K34: HA pâtisseries vacances fév./ FA. 2502HY0232120 DU 18/02/25 CL25002001 - PATISSERIE VAC DE FEVRIER ELEM 2 | L34: 27.47 | M34: 2.17 | N34: 29.64 | P34: 45726 | Q34: 29.64 | R34: CL25002001 | S34: 0 | Z34: 0 | AA34: 0 | AB34: 0 | AD34: 1507 | AE34: AUCHAN HYPERMARCHE | AG34: 331 | AH34: 60623 | AK34: 4-CT | AL34: CLMICH | AM34: 011 | AN34: CHARGES A CARACTERE GENERAL | AO34: 011 | AP34: CHARGES A CARACTERE GENERAL | BH34: 20250336 | BI34: 1 | BJ34: 0 | BN34: 45726 | BO34: 45726 | BP34: 29.64 | BQ34: 45725
A35: Mandat ordinaire | C35: 2025 | D35: CR | E35: 403208 | F35: 289 | G35: 43 | H35: 0 | I35: 45715 | J35: CSFF | K35: FAC. 2502HY0203412 DU 12/02/2025 PATISSERIE FEVRIER 1 LM | L35: 27.42 | M35: 1.51 | N35: 28.93 | P35: 45726 | Q35: 28.93 | R35: CL25001101 | S35: 0 | Z35: 0 | AA35: 0 | AB35: 0 | AD35: 1507 | AE35: AUCHAN HYPERMARCHE | AG35: 331 | AH35: 60623 | AK35: 4-CT | AL35: CLMICH | AM35: 011 | AN35: CHARGES A CARACTERE GENERAL | AO35: 011 | AP35: CHARGES A CARACTERE GENERAL | BH35: 20250292 | BI35: 1 | BJ35: 0 | BN35: 45726 | BO35: 45726 | BP35: 28.93 | BQ35: 45725
A36: Mandat ordinaire | C36: 2025 | D36: CR | E36: 403209 | F36: 290 | G36: 43 | H36: 0 | I36: 45715 | J36: CSFF | K36: FAC. 2502HY0203413 DU 12/02/2025 PATISSERIE FEVRIER 2 LM | L36: 26.15 | M36: 1.66 | N36: 27.81 | P36: 45726 | Q36: 27.81 | R36: CL25001201 | S36: 0 | Z36: 0 | AA36: 0 | AB36: 0 | AD36: 1507 | AE36: AUCHAN HYPERMARCHE | AG36: 331 | AH36: 60623 | AK36: 4-CT | AL36: CLMICH | AM36: 011 | AN36: CHARGES A CARACTERE GENERAL | AO36: 011 | AP36: CHARGES A CARACTERE GENERAL | BH36: 20250293 | BI36: 1 | BJ36: 0 | BN36: 45726 | BO36: 45726 | BP36: 27.81 | BQ36: 45725
A37: Mandat ordinaire | C37: 2025 | D37: CR | E37: 403211 | F37: 291 | G37: 43 | H37: 0 | I37: 45715 | J37: CSFF | K37: FAC. 2502HY0232118 DU 18/02/2025 PATISSERIE VAC DE FEVRIER MATER 1 LM | L37: 25.48 | M37: 3.6 | N37: 29.08 | P37: 45726 | Q37: 29.08 | R37: CL25001701 | S37: 0 | Z37: 0 | AA37: 0 | AB37: 0 | AD37: 1507 | AE37: AUCHAN HYPERMARCHE | AG37: 331 | AH37: 60623 | AK37: 4-CT | AL37: CLMICH | AM37: 011 | AN37: CHARGES A CARACTERE GENERAL | AO37: 011 | AP37: CHARGES A CARACTERE GENERAL | BH37: 20250337 | BI37: 1 | BJ37: 0 | BN37: 45726 | BO37: 45726 | BP37: 29.08 | BQ37: 45725
A38: Mandat ordinaire | C38: 2025 | D38: CR | E38: 403213 | F38: 293 | G38: 43 | H38: 0 | I38: 45715 | J38: CSFF | K38: FAC. 2502HY0250713 DU 20/02/2025 PATISSERIE VAC DE FEVRIER MATER 2 LM | L38: 28.44 | M38: 1.56 | N38: 30 | P38: 45726 | Q38: 30 | R38: CL25001801 | S38: 0 | Z38: 0 | AA38: 0 | AB38: 0 | AD38: 1507 | AE38: AUCHAN HYPERMARCHE | AG38: 331 | AH38: 60623 | AK38: 4-CT | AL38: CLMICH | AM38: 011 | AN38: CHARGES A CARACTERE GENERAL | AO38: 011 | AP38: CHARGES A CARACTERE GENERAL | BH38: 20250345 | BI38: 1 | BJ38: 0 | BN38: 45726 | BO38: 45726 | BP38: 30 | BQ38: 45725
A39: Mandat ordinaire | C39: 2025 | D39: CR | E39: 403214 | F39: 294 | G39: 43 | H39: 0 | I39: 45715 | J39: CSFF | K39: FAC. 2502HY0250716 DU 20/02/2025 VEILLEE PIZZA 20/02 LM | L39: 93.43 | M39: 5.96 | N39: 99.39 | P39: 45726 | Q39: 99.39 | R39: CL25001601 | S39: 0 | Z39: 0 | AA39: 0 | AB39: 0 | AD39: 1507 | AE39: AUCHAN HYPERMARCHE | AG39: 331 | AH39: 60623 | AK39: 4-CT | AL39: CLMICH | AM39: 011 | AN39: CHARGES A CARACTERE GENERAL | AO39: 011 | AP39: CHARGES A CARACTERE GENERAL | BH39: 20250346 | BI39: 1 | BJ39: 0 | BN39: 45726 | BO39: 45726 | BP39: 99.39 | BQ39: 45725
A40: Mandat ordinaire | C40: 2025 | D40: CR | E40: 403221 | F40: 299 | G40: 43 | H40: 0 | I40: 45715 | J40: CSFF | K40: FAC. 2502HY0273215 DU 25/02/2025 REPAS AU CLUB 01 VACANCES HIVERS 2025 CA | L40: 121.05 | M40: 24.21 | N40: 145.26 | P40: 45726 | Q40: 145.26 | R40: JS25000901 | S40: 0 | Z40: 0 | AA40: 0 | AB40: 0 | AD40: 1507 | AE40: AUCHAN HYPERMARCHE | AG40: 338 | AH40: 60623 | AK40: 4-JE | AL40: CA | AM40: 011 | AN40: CHARGES A CARACTERE GENERAL | AO40: 011 | AP40: CHARGES A CARACTERE GENERAL | BH40: 20250364 | BI40: 1 | BJ40: 0 | BN40: 45726 | BO40: 45726 | BP40: 145.26 | BQ40: 45725
...

Sheet DEP ALIM MODIF
A1: Type écriture | B1: Nb. ann/rej | C1: Exercice | D1: Budget | E1: N° écriture | F1: N° pièce | G1: N° bordereau | H1: N° ordre | I1: Date pièce | J1: Lot | K1: Libellé | L1: Montant HT | M1: Montant TVA | N1: Montant TTC | O1: Réf. dossier | P1: Date règlement | Q1: Montant pour le C.A. | R1: Engagement | S1: Solde eng. | T1: Mt révision HT | U1: Mt révision TVA | V1: Mt révision TTC | W1: Code contrat | X1: Code tiers | Y1: Libellé tiers | Z1: Fonction | AA1: Nature | AB1: Service | AC1: Antenne | AD1: Chapitre | AE1: Libellé chapitre | AF1: Cha. voté | AG1: Libellé chapitre voté | AH1: Nomenclature | AI1: Libellé nomenclature | AJ1: Inscription | AK1: N° facture | AL1: Nombre PJ | AM1: Nombre CA | AN1: Prise en charge | AO1: Acquittement du flux | AP1: Montant payé/encaissé | AQ1: Génération du flux
A2: Mandat ordinaire | C2: 2025 | D2: CR | E2: 401938 | F2: 65 | G2: 11 | H2: 0 | I2: 45698 | J2: ARFF | K2: FAC. 14D DU 31/12/2024 RS24009004R - RATT ACCUEIL LE PETIT PRINCE | L2: 28.16 | M2: 1.55 | N2: 29.71 | P2: 45701 | Q2: 29.71 | R2: RS24009004R | S2: 0 | T2: 0 | U2: 0 | V2: 0 | X2: 5384 | Y2: SAS VERMAR L ORGE ET LE BLE | Z2: 331 | AA2: 60623 | AB2: 2-RE | AC2: RESTGAV | AD2: 011 | AE2: CHARGES A CARACTERE GENERAL | AF2: 011 | AG2: CHARGES A CARACTERE GENERAL | AJ2: CPRAT - RATT ACCUEIL LE PETIT PRINCE | AK2: 20250140 | AL2: 1 | AM2: 0 | AN2: 45701 | AO2: 45701 | AP2: 29.71 | AQ2: 45700
A3: Mandat ordinaire | C3: 2025 | D3: CR | E3: 401939 | F3: 64 | G3: 11 | H3: 0 | I3: 45698 | J3: ARFF | K3: FAC. 16D DU 31/12/2024 RS24009001R - RATT RESTAURANT COMMUNAL | L3: 19.36 | M3: 1.06 | N3: 20.42 | P3: 45701 | Q3: 20.42 | R3: RS24009001R | S3: 0 | T3: 0 | U3: 0 | V3: 0 | X3: 5384 | Y3: SAS VERMAR L ORGE ET LE BLE | Z3: 020 | AA3: 60623 | AB3: 2-RE | AC3: RESTCOMM | AD3: 011 | AE3: CHARGES A CARACTERE GENERAL | AF3: 011 | AG3: CHARGES A CARACTERE GENERAL | AJ3: CPRAT - RATT RESTAURANT COMMUNAL | AK3: 20250139 | AL3: 1 | AM3: 0 | AN3: 45701 | AO3: 45701 | AP3: 20.42 | AQ3: 45700
A4: Mandat ordinaire | C4: 2025 | D4: CR | E4: 401940 | F4: 63 | G4: 11 | H4: 0 | I4: 45698 | J4: ARFF | K4: FAC. 12DEC DU 31/12/2024 RS24009002R - RATT RESTAURATION SCOLAIRE | L4: 696.96 | M4: 38.33 | N4: 735.29 | P4: 45701 | Q4: 735.29 | R4: RS24009002R | S4: 0 | T4: 0 | U4: 0 | V4: 0 | X4: 5384 | Y4: SAS VERMAR L ORGE ET LE BLE | Z4: 281 | AA4: 60623 | AB4: 2-RE | AD4: 011 | AE4: CHARGES A CARACTERE GENERAL | AF4: 011 | AG4: CHARGES A CARACTERE GENERAL | AJ4: CPRAT - RATT RESTAURATION SCOLAIRE | AK4: 20250138 | AL4: 1 | AM4: 0 | AN4: 45701 | AO4: 45701 | AP4: 735.29 | AQ4: 45700
A5: Mandat ordinaire | C5: 2025 | D5: CR | E5: 401942 | F5: 62 | G5: 11 | H5: 0 | I5: 45698 | J5: ARFF | K5: FAC. 13D DU 31/12/2024 RS24009003R - RATT ACCUEIL JP1 | L5: 28.16 | M5: 1.55 | N5: 29.71 | P5: 45701 | Q5: 29.71 | R5: RS24009003R | S5: 0 | T5: 0 | U5: 0 | V5: 0 | X5: 5384 | Y5: SAS VERMAR L ORGE ET LE BLE | Z5: 331 | AA5: 60623 | AB5: 2-RE | AC5: CLJP1 | AD5: 011 | AE5: CHARGES A CARACTERE GENERAL | AF5: 011 | AG5: CHARGES A CARACTERE GENERAL | AJ5: CPRAT - RATT ACCUEIL JP1 | AK5: 20250137 | AL5: 1 | AM5: 0 | AN5: 45701 | AO5: 45701 | AP5: 29.71 | AQ5: 45700
A6: Mandat ordinaire | C6: 2025 | D6: CR | E6: 401943 | F6: 61 | G6: 11 | H6: 0 | I6: 45698 | J6: ARFF | K6: FAC. 15D DU 31/12/2024 RS24009005R - RATT ACCUEIL LOUISE MICHEL | L6: 41.36 | M6: 2.27 | N6: 43.63 | P6: 45701 | Q6: 43.63 | R6: RS24009005R | S6: 0 | T6: 0 | U6: 0 | V6: 0 | X6: 5384 | Y6: SAS VERMAR L ORGE ET LE BLE | Z6: 331 | AA6: 60623 | AB6: 2-RE | AC6: RESTMICH | AD6: 011 | AE6: CHARGES A CARACTERE GENERAL | AF6: 011 | AG6: CHARGES A CARACTERE GENERAL | AJ6: CPRAT - RATT ACCUEIL LOUISE MICHEL | AK6: 20250136 | AL6: 1 | AM6: 0 | AN6: 45701 | AO6: 45701 | AP6: 43.63 | AQ6: 45700
A7: Mandat ordinaire | C7: 2025 | D7: CR | E7: 402989 | F7: 148 | G7: 22 | H7: 5 | I7: 45705 | J7: RADE | K7: REGULARISATION RA 20052 ETATS 7.8 | L7: 115.88 | M7: 23.18 | N7: 139.06 | P7: 45720 | Q7: 139.06 | S7: 0 | T7: 0 | U7: 0 | V7: 0 | X7: 1462 | Y7: RA 20052 AFFAIRES GENERALES | Z7: 020 | AA7: 60623 | AB7: 0-CA | AC7: CAB | AD7: 011 | AE7: CHARGES A CARACTERE GENERAL | AF7: 011 | AG7: CHARGES A CARACTERE GENERAL | AL7: 1 | AM7: 0 | AN7: 45720 | AO7: 45714 | AP7: 139.06 | AQ7: 45713
A8: Mandat ordinaire | C8: 2025 | D8: CR | E8: 402990 | F8: 148 | G8: 22 | H8: 6 | I8: 45705 | J8: RADE | K8: REGULARISATION RA 20052 ETATS 6.10.11.12 | L8: 338.21 | M8: 67.64 | N8: 405.85 | P8: 45720 | Q8: 405.85 | S8: 0 | T8: 0 | U8: 0 | V8: 0 | X8: 1462 | Y8: RA 20052 AFFAIRES GENERALES | Z8: 311 | AA8: 60623 | AB8: 3-CU | AD8: 011 | AE8: CHARGES A CARACTERE GENERAL | AF8: 011 | AG8: CHARGES A CARACTERE GENERAL | AL8: 1 | AM8: 0 | AN8: 45720 | AO8: 45714 | AP8: 405.85 | AQ8: 45713
A9: Mandat ordinaire | C9: 2025 | D9: CR | E9: 403011 | F9: 182 | G9: 28 | H9: 0 | I9: 45706 | J9: CSFF | K9: RATT FAC. 2412HY1319371 DU 23/12/2024 JS24011601R - RATT GOUTERS VACANCES NOEL 2024 | L9: 185.57 | M9: 13.77 | N9: 199.34 | P9: 45715 | Q9: 199.34 | R9: JS24011601R | S9: 0 | T9: 0 | U9: 0 | V9: 0 | X9: 1507 | Y9: AUCHAN HYPERMARCHE | Z9: 338 | AA9: 60623 | AB9: 4-JE | AC9: CA | AD9: 011 | AE9: CHARGES A CARACTERE GENERAL | AF9: 011 | AG9: CHARGES A CARACTERE GENERAL | AJ9: CPRAT - RATT GOUTERS VACANCES NOEL 2024 | AK9: 20234517 | AL9: 1 | AM9: 0 | AN9: 45715 | AO9: 45714 | AP9: 199.34 | AQ9: 45713
A10: Mandat ordinaire | C10: 2025 | D10: CR | E10: 403075 | F10: 203 | G10: 28 | H10: 0 | I10: 45706 | J10: CSFF | K10: FAC. 2502HY0226458 DU 17/02/2025 PATISSERIE 01 VACANCES HIVERS 2025 | L10: 46.23 | M10: 2.54 | N10: 48.77 | P10: 45715 | Q10: 48.77 | R10: JS25000601 | S10: 0 | T10: 0 | U10: 0 | V10: 0 | X10: 1507 | Y10: AUCHAN HYPERMARCHE | Z10: 338 | AA10: 60623 | AB10: 4-JE | AC10: CA | AD10: 011 | AE10: CHARGES A CARACTERE GENERAL | AF10: 011 | AG10: CHARGES A CARACTERE GENERAL | AK10: 20250313 | AL10: 1 | AM10: 0 | AN10: 45715 | AO10: 45714 | AP10: 48.77 | AQ10: 45713
A11: Mandat ordinaire | C11: 2025 | D11: CR | E11: 403082 | F11: 246 | G11: 34 | H11: 0 | I11: 45712 | J11: MMFF | K11: Goûter vacances scolaires d'hiver 2025 FAC. 2502HY0232115 DU 18/02/2025 | L11: 181.58 | M11: 11.46 | N11: 193.04 | P11: 45714 | Q11: 193.04 | R11: JS25000501 | S11: 0 | T11: 0 | U11: 0 | V11: 0 | X11: 1507 | Y11: AUCHAN HYPERMARCHE | Z11: 338 | AA11: 60623 | AB11: 4-JE | AC11: CA | AD11: 011 | AE11: CHARGES A CARACTERE GENERAL | AF11: 011 | AG11: CHARGES A CARACTERE GENERAL | AK11: 20250338 | AL11: 1 | AM11: 0 | AN11: 45714 | AO11: 45713 | AP11: 193.04 | AQ11: 45712
A12: Mandat ordinaire | C12: 2025 | D12: CR | E12: 403084 | F12: 245 | G12: 34 | H12: 0 | I12: 45712 | J12: MMFF | K12: Repas au club 01 vacances hiver 2025 FAC. 2502HY0232145 DU 18/02/2025 | L12: 127.93 | M12: 7.04 | N12: 134.97 | P12: 45714 | Q12: 134.97 | R12: JS25000801 | S12: 0 | T12: 0 | U12: 0 | V12: 0 | X12: 1507 | Y12: AUCHAN HYPERMARCHE | Z12: 338 | AA12: 60623 | AB12: 4-JE | AC12: CA | AD12: 011 | AE12: CHARGES A CARACTERE GENERAL | AF12: 011 | AG12: CHARGES A CARACTERE GENERAL | AK12: 20250334 | AL12: 1 | AM12: 0 | AN12: 45714 | AO12: 45713 | AP12: 134.97 | AQ12: 45712
A13: Mandat ordinaire | C13: 2025 | D13: CR | E13: 403107 | F13: 219 | G13: 30 | H13: 0 | I13: 45709 | J13: CSFF | K13: FAC. 487 DU 31/01/2025 PAIN RESTAURANT COMMUNAL JANVIER | L13: 28.83 | M13: 1.59 | N13: 30.42 | P13: 45714 | Q13: 30.42 | R13: RS25001001 | S13: 0 | T13: 0 | U13: 0 | V13: 0 | X13: 7485 | Y13: SAS PATAUX LA CERISE SUR LE GATE | Z13: 020 | AA13: 60623 | AB13: 2-RE | AC13: RESTCOMM | AD13: 011 | AE13: CHARGES A CARACTERE GENERAL | AF13: 011 | AG13: CHARGES A CARACTERE GENERAL | AK13: 20250324 | AL13: 1 | AM13: 0 | AN13: 45714 | AO13: 45713 | AP13: 30.42 | AQ13: 45712
A14: Mandat ordinaire | C14: 2025 | D14: CR | E14: 403108 | F14: 220 | G14: 30 | H14: 0 | I14: 45709 | J14: CSFF | K14: FAC. 486 DU 31/01/2025 PAIN ACCUEIL LM JANVIER | L14: 66.54 | M14: 3.66 | N14: 70.2 | P14: 45714 | Q14: 70.2 | R14: RS25000801 | S14: 0 | T14: 0 | U14: 0 | V14: 0 | X14: 7485 | Y14: SAS PATAUX LA CERISE SUR LE GATE | Z14: 331 | AA14: 60623 | AB14: 2-RE | AC14: RESTMICH | AD14: 011 | AE14: CHARGES A CARACTERE GENERAL | AF14: 011 | AG14: CHARGES A CARACTERE GENERAL | AK14: 20250325 | AL14: 1 | AM14: 0 | AN14: 45714 | AO14: 45713 | AP14: 70.2 | AQ14: 45712
A15: Mandat ordinaire | C15: 2025 | D15: CR | E15: 403109 | F15: 221 | G15: 30 | H15: 0 | I15: 45709 | J15: CSFF | K15: FAC. 485 DU 31/01/2025 PAIN ACCUEIL PP JANVIER | L15: 53.23 | M15: 2.93 | N15: 56.16 | P15: 45714 | Q15: 56.16 | R15: RS25000701 | S15: 0 | T15: 0 | U15: 0 | V15: 0 | X15: 7485 | Y15: SAS PATAUX LA CERISE SUR LE GATE | Z15: 331 | AA15: 60623 | AB15: 2-RE | AC15: RESTGAV | AD15: 011 | AE15: CHARGES A CARACTERE GENERAL | AF15: 011 | AG15: CHARGES A CARACTERE GENERAL | AK15: 20250326 | AL15: 1 | AM15: 0 | AN15: 45714 | AO15: 45713 | AP15: 56.16 | AQ15: 45712
A16: Mandat ordinaire | C16: 2025 | D16: CR | E16: 403110 | F16: 222 | G16: 30 | H16: 0 | I16: 45709 | J16: CSFF | K16: FAC. 484 DU 31/01/2025 PAIN ACCUEIL JP1 JANVIER | L16: 53.23 | M16: 2.93 | N16: 56.16 | P16: 45714 | Q16: 56.16 | R16: RS25000901 | S16: 0 | T16: 0 | U16: 0 | V16: 0 | X16: 7485 | Y16: SAS PATAUX LA CERISE SUR LE GATE | Z16: 331 | AA16: 60623 | AB16: 2-RE | AC16: CLJP1 | AD16: 011 | AE16: CHARGES A CARACTERE GENERAL | AF16: 011 | AG16: CHARGES A CARACTERE GENERAL | AK16: 20250327 | AL16: 1 | AM16: 0 | AN16: 45714 | AO16: 45713 | AP16: 56.16 | AQ16: 45712
A17: Mandat ordinaire | C17: 2025 | D17: CR | E17: 403111 | F17: 223 | G17: 30 | H17: 0 | I17: 45709 | J17: CSFF | K17: FAC. 483 DU 31/01/2025 PAIN POUR LA RESTAURATION SCOLAIRE JANVIER | L17: 1255.39 | M17: 69.05 | N17: 1324.44 | P17: 45714 | Q17: 1324.44 | R17: RS25000601 | S17: 0 | T17: 0 | U17: 0 | V17: 0 | X17: 7485 | Y17: SAS PATAUX LA CERISE SUR LE GATE | Z17: 281 | AA17: 60623 | AB17: 2-RE | AD17: 011 | AE17: CHARGES A CARACTERE GENERAL | AF17: 011 | AG17: CHARGES A CARACTERE GENERAL | AK17: 20250328 | AL17: 1 | AM17: 0 | AN17: 45714 | AO17: 45713 | AP17: 1324.44 | AQ17: 45712
A18: Mandat ordinaire | C18: 2025 | D18: CR | E18: 403112 | F18: 224 | G18: 30 | H18: 0 | I18: 45709 | J18: CSFF | K18: FAC. 455 DU 19/12/2024 RATT MINI VIENNOISERIES JP1 | L18: 389.43 | M18: 21.42 | N18: 410.85 | P18: 45714 | Q18: 410.85 | R18: SC24020701R | S18: 0 | T18: 0 | U18: 0 | V18: 0 | X18: 7485 | Y18: SAS PATAUX LA CERISE SUR LE GATE | Z18: 201 | AA18: 60623 | AB18: 2-SC | AD18: 011 | AE18: CHARGES A CARACTERE GENERAL | AF18: 011 | AG18: CHARGES A CARACTERE GENERAL | AJ18: CPRAT - RATT MINI VIENNOISERIES JP1 | AK18: 20250329 | AL18: 1 | AM18: 0 | AN18: 45714 | AO18: 45713 | AP18: 410.85 | AQ18: 45712
A19: Mandat ordinaire | C19: 2025 | D19: CR | E19: 403165 | F19: 271 | G19: 39 | H19: 0 | I19: 45714 | J19: MMFF | K19: VIENNOISERIES - LEGISLATIVES JUIN 2024 RATT FAC. 394 DU 28/06/2024 | L19: 92.56 | M19: 5.09 | N19: 97.65 | P19: 45726 | Q19: 97.65 | R19: AG24002701R | S19: 0 | T19: 0 | U19: 0 | V19: 0 | X19: 7485 | Y19: SAS PATAUX LA CERISE SUR LE GATE | Z19: 026 | AA19: 60623 | AB19: 0-AG | AC19: ETATCIV | AD19: 011 | AE19: CHARGES A CARACTERE GENERAL | AF19: 011 | AG19: CHARGES A CARACTERE GENERAL | AJ19: CPRAT - RATT VIENNOISERIES LEGISLATIVES 30 JUIN | AK19: 20233053 | AL19: 1 | AM19: 0 | AN19: 45726 | AO19: 45726 | AP19: 97.65 | AQ19: 45725
A20: Mandat ordinaire | C20: 2025 | D20: CR | E20: 403191 | F20: 267 | G20: 39 | H20: 0 | I20: 45714 | J20: MMFF | K20: HA goûter et petit-déjeuner - FA. 2501HY0123697 du 28.01.25 FAC. 2501HY0123697 DU 28/01/2025 | L20: 141.16 | M20: 8.52 | N20: 149.68 | P20: 45726 | Q20: 149.68 | R20: CL25000101 | S20: 0 | T20: 0 | U20: 0 | V20: 0 | X20: 1507 | Y20: AUCHAN HYPERMARCHE | Z20: 331 | AA20: 60623 | AB20: 4-CT | AC20: CLMICH | AD20: 011 | AE20: CHARGES A CARACTERE GENERAL | AF20: 011 | AG20: CHARGES A CARACTERE GENERAL | AK20: 20250168 | AL20: 1 | AM20: 0 | AN20: 45726 | AO20: 45726 | AP20: 149.68 | AQ20: 45725
A21: Mandat ordinaire | C21: 2025 | D21: CR | E21: 403192 | F21: 268 | G21: 39 | H21: 0 | I21: 45714 | J21: MMFF | K21: HA repas CM2 du 29/01 - FAC. 2502HY0165620 DU 05/02/2025 CL25001001 - REPAS DES CHAMPIONS 29/01 REPAS DES CM2 SUR LA | L21: 119.61 | M21: 7.73 | N21: 127.34 | P21: 45726 | Q21: 127.34 | R21: CL25001001 | S21: 0 | T21: 0 | U21: 0 | V21: 0 | X21: 1507 | Y21: AUCHAN HYPERMARCHE | Z21: 331 | AA21: 60623 | AB21: 4-CT | AC21: CLMICH | AD21: 011 | AE21: CHARGES A CARACTERE GENERAL | AF21: 011 | AG21: CHARGES A CARACTERE GENERAL | AK21: 20250276 | AL21: 1 | AM21: 0 | AN21: 45726 | AO21: 45726 | AP21: 127.34 | AQ21: 45725
A22: Mandat ordinaire | C22: 2025 | D22: CR | E22: 403193 | F22: 269 | G22: 39 | H22: 0 | I22: 45714 | J22: MMFF | K22: HA repas créole gp CP - FAC. 2502HY0232136 DU 18/02/2025 CL25002201 - REPAS CREOLE GROUPE DES CP 27/02 | L22: 93.69 | M22: 6.3 | N22: 99.99 | P22: 45726 | Q22: 99.99 | R22: CL25002201 | S22: 0 | T22: 0 | U22: 0 | V22: 0 | X22: 1507 | Y22: AUCHAN HYPERMARCHE | Z22: 331 | AA22: 60623 | AB22: 4-CT | AC22: CLMICH | AD22: 011 | AE22: CHARGES A CARACTERE GENERAL | AF22: 011 | AG22: CHARGES A CARACTERE GENERAL | AK22: 20250335 | AL22: 1 | AM22: 0 | AN22: 45726 | AO22: 45726 | AP22: 99.99 | AQ22: 45725
A23: Mandat ordinaire | C23: 2025 | D23: CR | E23: 403194 | F23: 270 | G23: 39 | H23: 0 | I23: 45714 | J23: MMFF | K23: HA pâtisseries vacances fév./ FA. 2502HY0232120 DU 18/02/25 CL25002001 - PATISSERIE VAC DE FEVRIER ELEM 2 | L23: 27.47 | M23: 2.17 | N23: 29.64 | P23: 45726 | Q23: 29.64 | R23: CL25002001 | S23: 0 | T23: 0 | U23: 0 | V23: 0 | X23: 1507 | Y23: AUCHAN HYPERMARCHE | Z23: 331 | AA23: 60623 | AB23: 4-CT | AC23: CLMICH | AD23: 011 | AE23: CHARGES A CARACTERE GENERAL | AF23: 011 | AG23: CHARGES A CARACTERE GENERAL | AK23: 20250336 | AL23: 1 | AM23: 0 | AN23: 45726 | AO23: 45726 | AP23: 29.64 | AQ23: 45725
A24: Mandat ordinaire | C24: 2025 | D24: CR | E24: 403208 | F24: 289 | G24: 43 | H24: 0 | I24: 45715 | J24: CSFF | K24: FAC. 2502HY0203412 DU 12/02/2025 PATISSERIE FEVRIER 1 LM | L24: 27.42 | M24: 1.51 | N24: 28.93 | P24: 45726 | Q24: 28.93 | R24: CL25001101 | S24: 0 | T24: 0 | U24: 0 | V24: 0 | X24: 1507 | Y24: AUCHAN HYPERMARCHE | Z24: 331 | AA24: 60623 | AB24: 4-CT | AC24: CLMICH | AD24: 011 | AE24: CHARGES A CARACTERE GENERAL | AF24: 011 | AG24: CHARGES A CARACTERE GENERAL | AK24: 20250292 | AL24: 1 | AM24: 0 | AN24: 45726 | AO24: 45726 | AP24: 28.93 | AQ24: 45725
A25: Mandat ordinaire | C25: 2025 | D25: CR | E25: 403209 | F25: 290 | G25: 43 | H25: 0 | I25: 45715 | J25: CSFF | K25: FAC. 2502HY0203413 DU 12/02/2025 PATISSERIE FEVRIER 2 LM | L25: 26.15 | M25: 1.66 | N25: 27.81 | P25: 45726 | Q25: 27.81 | R25: CL25001201 | S25: 0 | T25: 0 | U25: 0 | V25: 0 | X25: 1507 | Y25: AUCHAN HYPERMARCHE | Z25: 331 | AA25: 60623 | AB25: 4-CT | AC25: CLMICH | AD25: 011 | AE25: CHARGES A CARACTERE GENERAL | AF25: 011 | AG25: CHARGES A CARACTERE GENERAL | AK25: 20250293 | AL25: 1 | AM25: 0 | AN25: 45726 | AO25: 45726 | AP25: 27.81 | AQ25: 45725
A26: Mandat ordinaire | C26: 2025 | D26: CR | E26: 403211 | F26: 291 | G26: 43 | H26: 0 | I26: 45715 | J26: CSFF | K26: FAC. 2502HY0232118 DU 18/02/2025 PATISSERIE VAC DE FEVRIER MATER 1 LM | L26: 25.48 | M26: 3.6 | N26: 29.08 | P26: 45726 | Q26: 29.08 | R26: CL25001701 | S26: 0 | T26: 0 | U26: 0 | V26: 0 | X26: 1507 | Y26: AUCHAN HYPERMARCHE | Z26: 331 | AA26: 60623 | AB26: 4-CT | AC26: CLMICH | AD26: 011 | AE26: CHARGES A CARACTERE GENERAL | AF26: 011 | AG26: CHARGES A CARACTERE GENERAL | AK26: 20250337 | AL26: 1 | AM26: 0 | AN26: 45726 | AO26: 45726 | AP26: 29.08 | AQ26: 45725
A27: Mandat ordinaire | C27: 2025 | D27: CR | E27: 403213 | F27: 293 | G27: 43 | H27: 0 | I27: 45715 | J27: CSFF | K27: FAC. 2502HY0250713 DU 20/02/2025 PATISSERIE VAC DE FEVRIER MATER 2 LM | L27: 28.44 | M27: 1.56 | N27: 30 | P27: 45726 | Q27: 30 | R27: CL25001801 | S27: 0 | T27: 0 | U27: 0 | V27: 0 | X27: 1507 | Y27: AUCHAN HYPERMARCHE | Z27: 331 | AA27: 60623 | AB27: 4-CT | AC27: CLMICH | AD27: 011 | AE27: CHARGES A CARACTERE GENERAL | AF27: 011 | AG27: CHARGES A CARACTERE GENERAL | AK27: 20250345 | AL27: 1 | AM27: 0 | AN27: 45726 | AO27: 45726 | AP27: 30 | AQ27: 45725
A28: Mandat ordinaire | C28: 2025 | D28: CR | E28: 403214 | F28: 294 | G28: 43 | H28: 0 | I28: 45715 | J28: CSFF | K28: FAC. 2502HY0250716 DU 20/02/2025 VEILLEE PIZZA 20/02 LM | L28: 93.43 | M28: 5.96 | N28: 99.39 | P28: 45726 | Q28: 99.39 | R28: CL25001601 | S28: 0 | T28: 0 | U28: 0 | V28: 0 | X28: 1507 | Y28: AUCHAN HYPERMARCHE | Z28: 331 | AA28: 60623 | AB28: 4-CT | AC28: CLMICH | AD28: 011 | AE28: CHARGES A CARACTERE GENERAL | AF28: 011 | AG28: CHARGES A CARACTERE GENERAL | AK28: 20250346 | AL28: 1 | AM28: 0 | AN28: 45726 | AO28: 45726 | AP28: 99.39 | AQ28: 45725
A29: Mandat ordinaire | C29: 2025 | D29: CR | E29: 403221 | F29: 299 | G29: 43 | H29: 0 | I29: 45715 | J29: CSFF | K29: FAC. 2502HY0273215 DU 25/02/2025 REPAS AU CLUB 01 VACANCES HIVERS 2025 CA | L29: 121.05 | M29: 24.21 | N29: 145.26 | P29: 45726 | Q29: 145.26 | R29: JS25000901 | S29: 0 | T29: 0 | U29: 0 | V29: 0 | X29: 1507 | Y29: AUCHAN HYPERMARCHE | Z29: 338 | AA29: 60623 | AB29: 4-JE | AC29: CA | AD29: 011 | AE29: CHARGES A CARACTERE GENERAL | AF29: 011 | AG29: CHARGES A CARACTERE GENERAL | AK29: 20250364 | AL29: 1 | AM29: 0 | AN29: 45726 | AO29: 45726 | AP29: 145.26 | AQ29: 45725
A30: Mandat ordinaire | C30: 2025 | D30: CR | E30: 403373 | F30: 486 | G30: 65 | H30: 0 | I30: 45736 | J30: CSFF | K30: FAC. 2502HY0216694 DU 14/02/2025 GOUTER DE BIENVENUE - 15 FEVRIER | L30: 138.07 | M30: 10.77 | N30: 148.84 | P30: 45741 | Q30: 148.84 | R30: JS25001201 | S30: 0 | T30: 0 | U30: 0 | V30: 0 | X30: 1507 | Y30: AUCHAN HYPERMARCHE | Z30: 338 | AA30: 60623 | AB30: 4-JE | AC30: MDJ | AD30: 011 | AE30: CHARGES A CARACTERE GENERAL | AF30: 011 | AG30: CHARGES A CARACTERE GENERAL | AK30: 20250304 | AL30: 1 | AM30: 0 | AN30: 45740 | AO30: 45740 | AP30: 148.84 | AQ30: 45739
A31: Mandat ordinaire | C31: 2025 | D31: CR | E31: 404335 | F31: 407 | G31: 58 | H31: 0 | I31: 45728 | J31: ARFF | K31: FAC. 50140202202 DU 14/01/2025 CL25000701 - GOUTER + PETIT DEJEUNER JP1 JANVIER 2025 | L31: 187.08 | M31: 11.81 | N31: 198.89 | P31: 45733 | Q31: 198.89 | R31: CL25000701 | S31: 0 | T31: 0 | U31: 0 | V31: 0 | X31: 7727 | Y31: INTERMARCHE ACROSNIM CROSNE | Z31: 331 | AA31: 60623 | AB31: 4-CT | AC31: CLJP1 | AD31: 011 | AE31: CHARGES A CARACTERE GENERAL | AF31: 011 | AG31: CHARGES A CARACTERE GENERAL | AK31: 20250473 | AL31: 1 | AM31: 0 | AN31: 45733 | AO31: 45733 | AP31: 198.89 | AQ31: 45732
... A35: Mandat ordinaire | C35: 2025 | D35: CR | E35: 405100 | F35: 406 | G35: 58 | H35: 0 | I35: 45728 | J35: ARFF | K35: FAC. 2502HY0292332 DU 26/02/2025 CL25002101 - VEILLEE DEGUSTATION ELEMENTAIRES 28/02 | L35: 78.69 | M35: 5.05 | N35: 83.74 | P35: 45733 | Q35: 83.74 | R35: CL25002101 | S35: 0 | T35: 0 | U35: 0 | V35: 0 | X35: 1507 | Y35: AUCHAN HYPERMARCHE | Z35: 331 | AA35: 60623 | AB35: 4-CT | AC35: CLMICH | AD35: 011 | AE35: CHARGES A CARACTERE GENERAL | AF35: 011 | AG35: CHARGES A CARACTERE GENERAL | AK35: 20250391 | AL35: 1 | AM35: 0 | AN35: 45733 | AO35: 45733 | AP35: 83.74 | AQ35: 45732
A36: Mandat ordinaire | C36: 2025 | D36: CR | E36: 406028 | F36: 440 | G36: 61 | H36: 0 | I36: 45736 | J36: ARFF | K36: RATT FAC. 2412HY1331121 DU 26/12/2024 CL24034001R - RATT PATISSERIE, VEILLEE, CHOCOLAT DE NOËL, GO | L36: 952.59 | M36: 68.59 | N36: 1021.18 | P36: 45741 | Q36: 1021.18 | R36: CL24034001R | S36: 0 | T36: 0 | U36: 0 | V36: 0 | X36: 1507 | Y36: AUCHAN HYPERMARCHE | Z36: 331 | AA36: 60623 | AB36: 4-CT | AC36: CLGAV | AD36: 011 | AE36: CHARGES A CARACTERE GENERAL | AF36: 011 | AG36: CHARGES A CARACTERE GENERAL | AJ36: CPRAT - RATT PATISSERIE, VEILLEE, CHOCOLAT DE NOËL, GOUTER DE F IN D | AK36: 20234547 | AL36: 1 | AM36: 0 | AN36: 45736 | AO36: 45736 | AP36: 1021.18 | AQ36: 45735
A37: Mandat ordinaire | C37: 2025 | D37: CR | E37: 406071 | F37: 490 | G37: 65 | H37: 0 | I37: 45736 | J37: CSFF | K37: FAC. 2502HY0273212 DU 25/02/2025 CL25003101 - LAITAGES, VIENOISERIE, | L37: 174.04 | M37: 9.57 | N37: 183.61 | P37: 45741 | Q37: 183.61 | R37: CL25003101 | S37: 0 | T37: 0 | U37: 0 | V37: 0 | X37: 1507 | Y37: AUCHAN HYPERMARCHE | Z37: 331 | AA37: 60623 | AB37: 4-CT | AC37: CLGAV | AD37: 011 | AE37: CHARGES A CARACTERE GENERAL | AF37: 011 | AG37: CHARGES A CARACTERE GENERAL | AK37: 20250363 | AL37: 1 | AM37: 0 | AN37: 45740 | AO37: 45740 | AP37: 183.61 | AQ37: 45739
A38: Mandat ordinaire | C38: 2025 | D38: CR | E38: 406085 | F38: 504 | G38: 65 | H38: 0 | I38: 45736 | J38: CSFF | K38: FAC. 2502HY0267380 DU 24/02/2025 CL25001901 - PATISSERIE VAC DE FEVRIER ELEM 1 | L38: 28.19 | M38: 1.55 | N38: 29.74 | P38: 45741 | Q38: 29.74 | R38: CL25001901 | S38: 0 | T38: 0 | U38: 0 | V38: 0 | X38: 1507 | Y38: AUCHAN HYPERMARCHE | Z38: 331 | AA38: 60623 | AB38: 4-CT | AC38: CLMICH | AD38: 011 | AE38: CHARGES A CARACTERE GENERAL | AF38: 011 | AG38: CHARGES A CARACTERE GENERAL | AK38: 20250365 | AL38: 1 | AM38: 0 | AN38: 45740 | AO38: 45740 | AP38: 29.74 | AQ38: 45739
A39: Mandat ordinaire | C39: 2025 | D39: CR | E39: 406086 | F39: 505 | G39: 65 | H39: 0 | I39: 45736 | J39: CSFF | K39: FAC. 2502HY0267376 DU 24/02/2025 CL25002301 - PATISSERIE VAC DE FEVRIER MATER 3 | L39: 27.88 | M39: 1.53 | N39: 29.41 | P39: 45741 | Q39: 29.41 | R39: CL25002301 | S39: 0 | T39: 0 | U39: 0 | V39: 0 | X39: 1507 | Y39: AUCHAN HYPERMARCHE | Z39: 331 | AA39: 60623 | AB39: 4-CT | AC39: CLMICH | AD39: 011 | AE39: CHARGES A CARACTERE GENERAL | AF39: 011 | AG39: CHARGES A CARACTERE GENERAL | AK39: 20250366 | AL39: 1 | AM39: 0 | AN39: 45740 | AO39: 45740 | AP39: 29.41 | AQ39: 45739
A40: Mandat ordinaire | C40: 2025 | D40: CR | E40: 406087 | F40: 506 | G40: 65 | H40: 0 | I40: 45736 | J40: CSFF | K40: FAC. 2502HY0267378 DU 24/02/2025 CL25000201 - GOUTERS ET PETITS DEJEUNERS JANVIER 2 | L40: 126.83 | M40: 8.32 | N40: 135.15 | P40: 45741 | Q40: 135.15 | R40: CL25000201 | S40: 0 | T40: 0 | U40: 0 | V40: 0 | X40: 1507 | Y40: AUCHAN HYPERMARCHE | Z40: 331 | AA40: 60623 | AB40: 4-CT | AC40: CLMICH | AD40: 011 | AE40: CHARGES A CARACTERE GENERAL | AF40: 011 | AG40: CHARGES A CARACTERE GENERAL | AK40: 20250367 | AL40: 1 | AM40: 0 | AN40: 45740 | AO40: 45740 | AP40: 135.15 | AQ40: 45739
